{"timestamp": "2025-10-17T22:54:25.343510+00:00", "logger": "ApiBackEnd", "level": "WARNING", "module": "error_handler", "function": "http_exception_handler", "line": 20, "message": "HTTPException: Resource not found"}
{"timestamp": "2025-10-17T22:54:25.352564+00:00", "logger": "ApiBackEnd", "level": "ERROR", "module": "error_handler", "function": "log_exceptions_middleware", "line": 13, "message": "Unexpected error occurred", "exception": "Traceback (most recent call last):\n  File \"/home/ronin/devops/apibackend/.venv/lib/python3.12/site-packages/starlette/middleware/base.py\", line 151, in call_next\n    message = await recv_stream.receive()\n              ^^^^^^^^^^^^^^^^^^^^^^^^^^^\n  File \"/home/ronin/devops/apibackend/.venv/lib/python3.12/site-packages/anyio/streams/memory.py\", line 126, in receive\n    raise EndOfStream from None\nanyio.EndOfStream\n\nDuring handling of the above exception, another exception occurred:\n\nTraceback (most recent call last):\n  File \"/home/ronin/devops/apibackend/middleware/error_handler.py\", line 10, in log_exceptions_middleware\n    response = await call_next(request)\n               ^^^^^^^^^^^^^^^^^^^^^^^^\n  File \"/home/ronin/devops/apibackend/.venv/lib/python3.12/site-packages/starlette/middleware/base.py\", line 159, in call_next\n    raise app_exc\n  File \"/home/ronin/devops/apibackend/.venv/lib/python3.12/site-packages/starlette/middleware/base.py\", line 144, in coro\n    await self.app(scope, receive_or_disconnect, send_no_error)\n  File \"/home/ronin/devops/apibackend/.venv/lib/python3.12/site-packages/starlette/middleware/exceptions.py\", line 63, in __call__\n    await wrap_app_handling_exceptions(self.app, conn)(scope, receive, send)\n  File \"/home/ronin/devops/apibackend/.venv/lib/python3.12/site-packages/starlette/_exception_handler.py\", line 53, in wrapped_app\n    raise exc\n  File \"/home/ronin/devops/apibackend/.venv/lib/python3.12/site-packages/starlette/_exception_handler.py\", line 42, in wrapped_app\n    await app(scope, receive, sender)\n  File \"/home/ronin/devops/apibackend/.venv/lib/python3.12/site-packages/fastapi/middleware/asyncexitstack.py\", line 18, in __call__\n    await self.app(scope, receive, send)\n  File \"/home/ronin/devops/apibackend/.venv/lib/python3.12/site-packages/starlette/routing.py\", line 716, in __call__\n    await self.middleware_stack(scope, receive, send)\n  File \"/home/ronin/devops/apibackend/.venv/lib/python3.12/site-packages/starlette/routing.py\", line 736, in app\n    await route.handle(scope, receive, send)\n  File \"/home/ronin/devops/apibackend/.venv/lib/python3.12/site-packages/starlette/routing.py\", line 290, in handle\n    await self.app(scope, receive, send)\n  File \"/home/ronin/devops/apibackend/.venv/lib/python3.12/site-packages/fastapi/routing.py\", line 123, in app\n    await wrap_app_handling_exceptions(app, request)(scope, receive, send)\n  File \"/home/ronin/devops/apibackend/.venv/lib/python3.12/site-packages/starlette/_exception_handler.py\", line 53, in wrapped_app\n    raise exc\n  File \"/home/ronin/devops/apibackend/.venv/lib/python3.12/site-packages/starlette/_exception_handler.py\", line 42, in wrapped_app\n    await app(scope, receive, sender)\n  File \"/home/ronin/devops/apibackend/.venv/lib/python3.12/site-packages/fastapi/routing.py\", line 109, in app\n    response = await f(request)\n               ^^^^^^^^^^^^^^^^\n  File \"/home/ronin/devops/apibackend/.venv/lib/python3.12/site-packages/fastapi/routing.py\", line 389, in app\n    raw_response = await run_endpoint_function(\n                   ^^^^^^^^^^^^^^^^^^^^^^^^^^^^\n  File \"/home/ronin/devops/apibackend/.venv/lib/python3.12/site-packages/fastapi/routing.py\", line 290, in run_endpoint_function\n    return await run_in_threadpool(dependant.call, **values)\n           ^^^^^^^^^^^^^^^^^^^^^^^^^^^^^^^^^^^^^^^^^^^^^^^^^\n  File \"/home/ronin/devops/apibackend/.venv/lib/python3.12/site-packages/starlette/concurrency.py\", line 38, in run_in_threadpool\n    return await anyio.to_thread.run_sync(func)\n           ^^^^^^^^^^^^^^^^^^^^^^^^^^^^^^^^^^^^\n  File \"/home/ronin/devops/apibackend/.venv/lib/python3.12/site-packages/anyio/to_thread.py\", line 56, in run_sync\n    return await get_async_backend().run_sync_in_worker_thread(\n           ^^^^^^^^^^^^^^^^^^^^^^^^^^^^^^^^^^^^^^^^^^^^^^^^^^^^\n  File \"/home/ronin/devops/apibackend/.venv/lib/python3.12/site-packages/anyio/_backends/_asyncio.py\", line 2485, in run_sync_in_worker_thread\n    return await future\n           ^^^^^^^^^^^^\n  File \"/home/ronin/devops/apibackend/.venv/lib/python3.12/site-packages/anyio/_backends/_asyncio.py\", line 976, in run\n    result = context.run(func, *args)\n             ^^^^^^^^^^^^^^^^^^^^^^^^\n  File \"/home/ronin/devops/apibackend/tests/11_test_error_logging.py\", line 24, in raise_exception\n    raise ValueError(\"Unexpected error occurred\")\nValueError: Unexpected error occurred"}
