{"timestamp": "2025-10-15T23:57:27.330438", "level": "ERROR", "module": "auth", "function": "register", "line": 47, "message": "Error during registration: (sqlite3.OperationalError) no such table: users\n[SQL: SELECT users.id AS users_id, users.username AS users_username, users.first_name AS users_first_name, users.last_name AS users_last_name, users.email AS users_email, users.password AS users_password, users.is_active AS users_is_active, users.is_staff AS users_is_staff, users.is_superuser AS users_is_superuser \nFROM users \nWHERE users.email = ?\n LIMIT ? OFFSET ?]\n[parameters: ('newuser@example.com', 1, 0)]\n(Background on this error at: https://sqlalche.me/e/20/e3q8)", "exception": "Traceback (most recent call last):\n  File \"/home/ronin/devops/apibackend/.venv/lib/python3.12/site-packages/sqlalchemy/engine/base.py\", line 1967, in _exec_single_context\n    self.dialect.do_execute(\n  File \"/home/ronin/devops/apibackend/.venv/lib/python3.12/site-packages/sqlalchemy/engine/default.py\", line 951, in do_execute\n    cursor.execute(statement, parameters)\nsqlite3.OperationalError: no such table: users\n\nThe above exception was the direct cause of the following exception:\n\nTraceback (most recent call last):\n  File \"/home/ronin/devops/apibackend/routers/auth.py\", line 26, in register\n    existing_user = db.query(User).filter(User.email == user.email).first()\n                    ^^^^^^^^^^^^^^^^^^^^^^^^^^^^^^^^^^^^^^^^^^^^^^^^^^^^^^^\n  File \"/home/ronin/devops/apibackend/.venv/lib/python3.12/site-packages/sqlalchemy/orm/query.py\", line 2759, in first\n    return self.limit(1)._iter().first()  # type: ignore\n           ^^^^^^^^^^^^^^^^^^^^^\n  File \"/home/ronin/devops/apibackend/.venv/lib/python3.12/site-packages/sqlalchemy/orm/query.py\", line 2857, in _iter\n    result: Union[ScalarResult[_T], Result[_T]] = self.session.execute(\n                                                  ^^^^^^^^^^^^^^^^^^^^^\n  File \"/home/ronin/devops/apibackend/.venv/lib/python3.12/site-packages/sqlalchemy/orm/session.py\", line 2351, in execute\n    return self._execute_internal(\n           ^^^^^^^^^^^^^^^^^^^^^^^\n  File \"/home/ronin/devops/apibackend/.venv/lib/python3.12/site-packages/sqlalchemy/orm/session.py\", line 2249, in _execute_internal\n    result: Result[Any] = compile_state_cls.orm_execute_statement(\n                          ^^^^^^^^^^^^^^^^^^^^^^^^^^^^^^^^^^^^^^^^\n  File \"/home/ronin/devops/apibackend/.venv/lib/python3.12/site-packages/sqlalchemy/orm/context.py\", line 306, in orm_execute_statement\n    result = conn.execute(\n             ^^^^^^^^^^^^^\n  File \"/home/ronin/devops/apibackend/.venv/lib/python3.12/site-packages/sqlalchemy/engine/base.py\", line 1419, in execute\n    return meth(\n           ^^^^^\n  File \"/home/ronin/devops/apibackend/.venv/lib/python3.12/site-packages/sqlalchemy/sql/elements.py\", line 526, in _execute_on_connection\n    return connection._execute_clauseelement(\n           ^^^^^^^^^^^^^^^^^^^^^^^^^^^^^^^^^^\n  File \"/home/ronin/devops/apibackend/.venv/lib/python3.12/site-packages/sqlalchemy/engine/base.py\", line 1641, in _execute_clauseelement\n    ret = self._execute_context(\n          ^^^^^^^^^^^^^^^^^^^^^^\n  File \"/home/ronin/devops/apibackend/.venv/lib/python3.12/site-packages/sqlalchemy/engine/base.py\", line 1846, in _execute_context\n    return self._exec_single_context(\n           ^^^^^^^^^^^^^^^^^^^^^^^^^^\n  File \"/home/ronin/devops/apibackend/.venv/lib/python3.12/site-packages/sqlalchemy/engine/base.py\", line 1986, in _exec_single_context\n    self._handle_dbapi_exception(\n  File \"/home/ronin/devops/apibackend/.venv/lib/python3.12/site-packages/sqlalchemy/engine/base.py\", line 2355, in _handle_dbapi_exception\n    raise sqlalchemy_exception.with_traceback(exc_info[2]) from e\n  File \"/home/ronin/devops/apibackend/.venv/lib/python3.12/site-packages/sqlalchemy/engine/base.py\", line 1967, in _exec_single_context\n    self.dialect.do_execute(\n  File \"/home/ronin/devops/apibackend/.venv/lib/python3.12/site-packages/sqlalchemy/engine/default.py\", line 951, in do_execute\n    cursor.execute(statement, parameters)\nsqlalchemy.exc.OperationalError: (sqlite3.OperationalError) no such table: users\n[SQL: SELECT users.id AS users_id, users.username AS users_username, users.first_name AS users_first_name, users.last_name AS users_last_name, users.email AS users_email, users.password AS users_password, users.is_active AS users_is_active, users.is_staff AS users_is_staff, users.is_superuser AS users_is_superuser \nFROM users \nWHERE users.email = ?\n LIMIT ? OFFSET ?]\n[parameters: ('newuser@example.com', 1, 0)]\n(Background on this error at: https://sqlalche.me/e/20/e3q8)"}
{"timestamp": "2025-10-15T23:57:27.360945", "level": "ERROR", "module": "auth", "function": "register", "line": 47, "message": "Error during registration: (sqlite3.OperationalError) no such table: users\n[SQL: SELECT users.id AS users_id, users.username AS users_username, users.first_name AS users_first_name, users.last_name AS users_last_name, users.email AS users_email, users.password AS users_password, users.is_active AS users_is_active, users.is_staff AS users_is_staff, users.is_superuser AS users_is_superuser \nFROM users \nWHERE users.email = ?\n LIMIT ? OFFSET ?]\n[parameters: ('duplicate@example.com', 1, 0)]\n(Background on this error at: https://sqlalche.me/e/20/e3q8)", "exception": "Traceback (most recent call last):\n  File \"/home/ronin/devops/apibackend/.venv/lib/python3.12/site-packages/sqlalchemy/engine/base.py\", line 1967, in _exec_single_context\n    self.dialect.do_execute(\n  File \"/home/ronin/devops/apibackend/.venv/lib/python3.12/site-packages/sqlalchemy/engine/default.py\", line 951, in do_execute\n    cursor.execute(statement, parameters)\nsqlite3.OperationalError: no such table: users\n\nThe above exception was the direct cause of the following exception:\n\nTraceback (most recent call last):\n  File \"/home/ronin/devops/apibackend/routers/auth.py\", line 26, in register\n    existing_user = db.query(User).filter(User.email == user.email).first()\n                    ^^^^^^^^^^^^^^^^^^^^^^^^^^^^^^^^^^^^^^^^^^^^^^^^^^^^^^^\n  File \"/home/ronin/devops/apibackend/.venv/lib/python3.12/site-packages/sqlalchemy/orm/query.py\", line 2759, in first\n    return self.limit(1)._iter().first()  # type: ignore\n           ^^^^^^^^^^^^^^^^^^^^^\n  File \"/home/ronin/devops/apibackend/.venv/lib/python3.12/site-packages/sqlalchemy/orm/query.py\", line 2857, in _iter\n    result: Union[ScalarResult[_T], Result[_T]] = self.session.execute(\n                                                  ^^^^^^^^^^^^^^^^^^^^^\n  File \"/home/ronin/devops/apibackend/.venv/lib/python3.12/site-packages/sqlalchemy/orm/session.py\", line 2351, in execute\n    return self._execute_internal(\n           ^^^^^^^^^^^^^^^^^^^^^^^\n  File \"/home/ronin/devops/apibackend/.venv/lib/python3.12/site-packages/sqlalchemy/orm/session.py\", line 2249, in _execute_internal\n    result: Result[Any] = compile_state_cls.orm_execute_statement(\n                          ^^^^^^^^^^^^^^^^^^^^^^^^^^^^^^^^^^^^^^^^\n  File \"/home/ronin/devops/apibackend/.venv/lib/python3.12/site-packages/sqlalchemy/orm/context.py\", line 306, in orm_execute_statement\n    result = conn.execute(\n             ^^^^^^^^^^^^^\n  File \"/home/ronin/devops/apibackend/.venv/lib/python3.12/site-packages/sqlalchemy/engine/base.py\", line 1419, in execute\n    return meth(\n           ^^^^^\n  File \"/home/ronin/devops/apibackend/.venv/lib/python3.12/site-packages/sqlalchemy/sql/elements.py\", line 526, in _execute_on_connection\n    return connection._execute_clauseelement(\n           ^^^^^^^^^^^^^^^^^^^^^^^^^^^^^^^^^^\n  File \"/home/ronin/devops/apibackend/.venv/lib/python3.12/site-packages/sqlalchemy/engine/base.py\", line 1641, in _execute_clauseelement\n    ret = self._execute_context(\n          ^^^^^^^^^^^^^^^^^^^^^^\n  File \"/home/ronin/devops/apibackend/.venv/lib/python3.12/site-packages/sqlalchemy/engine/base.py\", line 1846, in _execute_context\n    return self._exec_single_context(\n           ^^^^^^^^^^^^^^^^^^^^^^^^^^\n  File \"/home/ronin/devops/apibackend/.venv/lib/python3.12/site-packages/sqlalchemy/engine/base.py\", line 1986, in _exec_single_context\n    self._handle_dbapi_exception(\n  File \"/home/ronin/devops/apibackend/.venv/lib/python3.12/site-packages/sqlalchemy/engine/base.py\", line 2355, in _handle_dbapi_exception\n    raise sqlalchemy_exception.with_traceback(exc_info[2]) from e\n  File \"/home/ronin/devops/apibackend/.venv/lib/python3.12/site-packages/sqlalchemy/engine/base.py\", line 1967, in _exec_single_context\n    self.dialect.do_execute(\n  File \"/home/ronin/devops/apibackend/.venv/lib/python3.12/site-packages/sqlalchemy/engine/default.py\", line 951, in do_execute\n    cursor.execute(statement, parameters)\nsqlalchemy.exc.OperationalError: (sqlite3.OperationalError) no such table: users\n[SQL: SELECT users.id AS users_id, users.username AS users_username, users.first_name AS users_first_name, users.last_name AS users_last_name, users.email AS users_email, users.password AS users_password, users.is_active AS users_is_active, users.is_staff AS users_is_staff, users.is_superuser AS users_is_superuser \nFROM users \nWHERE users.email = ?\n LIMIT ? OFFSET ?]\n[parameters: ('duplicate@example.com', 1, 0)]\n(Background on this error at: https://sqlalche.me/e/20/e3q8)"}
{"timestamp": "2025-10-15T23:57:27.365544", "level": "ERROR", "module": "auth", "function": "register", "line": 47, "message": "Error during registration: (sqlite3.OperationalError) no such table: users\n[SQL: SELECT users.id AS users_id, users.username AS users_username, users.first_name AS users_first_name, users.last_name AS users_last_name, users.email AS users_email, users.password AS users_password, users.is_active AS users_is_active, users.is_staff AS users_is_staff, users.is_superuser AS users_is_superuser \nFROM users \nWHERE users.email = ?\n LIMIT ? OFFSET ?]\n[parameters: ('duplicate2@example.com', 1, 0)]\n(Background on this error at: https://sqlalche.me/e/20/e3q8)", "exception": "Traceback (most recent call last):\n  File \"/home/ronin/devops/apibackend/.venv/lib/python3.12/site-packages/sqlalchemy/engine/base.py\", line 1967, in _exec_single_context\n    self.dialect.do_execute(\n  File \"/home/ronin/devops/apibackend/.venv/lib/python3.12/site-packages/sqlalchemy/engine/default.py\", line 951, in do_execute\n    cursor.execute(statement, parameters)\nsqlite3.OperationalError: no such table: users\n\nThe above exception was the direct cause of the following exception:\n\nTraceback (most recent call last):\n  File \"/home/ronin/devops/apibackend/routers/auth.py\", line 26, in register\n    existing_user = db.query(User).filter(User.email == user.email).first()\n                    ^^^^^^^^^^^^^^^^^^^^^^^^^^^^^^^^^^^^^^^^^^^^^^^^^^^^^^^\n  File \"/home/ronin/devops/apibackend/.venv/lib/python3.12/site-packages/sqlalchemy/orm/query.py\", line 2759, in first\n    return self.limit(1)._iter().first()  # type: ignore\n           ^^^^^^^^^^^^^^^^^^^^^\n  File \"/home/ronin/devops/apibackend/.venv/lib/python3.12/site-packages/sqlalchemy/orm/query.py\", line 2857, in _iter\n    result: Union[ScalarResult[_T], Result[_T]] = self.session.execute(\n                                                  ^^^^^^^^^^^^^^^^^^^^^\n  File \"/home/ronin/devops/apibackend/.venv/lib/python3.12/site-packages/sqlalchemy/orm/session.py\", line 2351, in execute\n    return self._execute_internal(\n           ^^^^^^^^^^^^^^^^^^^^^^^\n  File \"/home/ronin/devops/apibackend/.venv/lib/python3.12/site-packages/sqlalchemy/orm/session.py\", line 2249, in _execute_internal\n    result: Result[Any] = compile_state_cls.orm_execute_statement(\n                          ^^^^^^^^^^^^^^^^^^^^^^^^^^^^^^^^^^^^^^^^\n  File \"/home/ronin/devops/apibackend/.venv/lib/python3.12/site-packages/sqlalchemy/orm/context.py\", line 306, in orm_execute_statement\n    result = conn.execute(\n             ^^^^^^^^^^^^^\n  File \"/home/ronin/devops/apibackend/.venv/lib/python3.12/site-packages/sqlalchemy/engine/base.py\", line 1419, in execute\n    return meth(\n           ^^^^^\n  File \"/home/ronin/devops/apibackend/.venv/lib/python3.12/site-packages/sqlalchemy/sql/elements.py\", line 526, in _execute_on_connection\n    return connection._execute_clauseelement(\n           ^^^^^^^^^^^^^^^^^^^^^^^^^^^^^^^^^^\n  File \"/home/ronin/devops/apibackend/.venv/lib/python3.12/site-packages/sqlalchemy/engine/base.py\", line 1641, in _execute_clauseelement\n    ret = self._execute_context(\n          ^^^^^^^^^^^^^^^^^^^^^^\n  File \"/home/ronin/devops/apibackend/.venv/lib/python3.12/site-packages/sqlalchemy/engine/base.py\", line 1846, in _execute_context\n    return self._exec_single_context(\n           ^^^^^^^^^^^^^^^^^^^^^^^^^^\n  File \"/home/ronin/devops/apibackend/.venv/lib/python3.12/site-packages/sqlalchemy/engine/base.py\", line 1986, in _exec_single_context\n    self._handle_dbapi_exception(\n  File \"/home/ronin/devops/apibackend/.venv/lib/python3.12/site-packages/sqlalchemy/engine/base.py\", line 2355, in _handle_dbapi_exception\n    raise sqlalchemy_exception.with_traceback(exc_info[2]) from e\n  File \"/home/ronin/devops/apibackend/.venv/lib/python3.12/site-packages/sqlalchemy/engine/base.py\", line 1967, in _exec_single_context\n    self.dialect.do_execute(\n  File \"/home/ronin/devops/apibackend/.venv/lib/python3.12/site-packages/sqlalchemy/engine/default.py\", line 951, in do_execute\n    cursor.execute(statement, parameters)\nsqlalchemy.exc.OperationalError: (sqlite3.OperationalError) no such table: users\n[SQL: SELECT users.id AS users_id, users.username AS users_username, users.first_name AS users_first_name, users.last_name AS users_last_name, users.email AS users_email, users.password AS users_password, users.is_active AS users_is_active, users.is_staff AS users_is_staff, users.is_superuser AS users_is_superuser \nFROM users \nWHERE users.email = ?\n LIMIT ? OFFSET ?]\n[parameters: ('duplicate2@example.com', 1, 0)]\n(Background on this error at: https://sqlalche.me/e/20/e3q8)"}
{"timestamp": "2025-10-15T23:57:27.373376", "level": "ERROR", "module": "auth", "function": "register", "line": 47, "message": "Error during registration: (sqlite3.OperationalError) no such table: users\n[SQL: SELECT users.id AS users_id, users.username AS users_username, users.first_name AS users_first_name, users.last_name AS users_last_name, users.email AS users_email, users.password AS users_password, users.is_active AS users_is_active, users.is_staff AS users_is_staff, users.is_superuser AS users_is_superuser \nFROM users \nWHERE users.email = ?\n LIMIT ? OFFSET ?]\n[parameters: ('loginuser@example.com', 1, 0)]\n(Background on this error at: https://sqlalche.me/e/20/e3q8)", "exception": "Traceback (most recent call last):\n  File \"/home/ronin/devops/apibackend/.venv/lib/python3.12/site-packages/sqlalchemy/engine/base.py\", line 1967, in _exec_single_context\n    self.dialect.do_execute(\n  File \"/home/ronin/devops/apibackend/.venv/lib/python3.12/site-packages/sqlalchemy/engine/default.py\", line 951, in do_execute\n    cursor.execute(statement, parameters)\nsqlite3.OperationalError: no such table: users\n\nThe above exception was the direct cause of the following exception:\n\nTraceback (most recent call last):\n  File \"/home/ronin/devops/apibackend/routers/auth.py\", line 26, in register\n    existing_user = db.query(User).filter(User.email == user.email).first()\n                    ^^^^^^^^^^^^^^^^^^^^^^^^^^^^^^^^^^^^^^^^^^^^^^^^^^^^^^^\n  File \"/home/ronin/devops/apibackend/.venv/lib/python3.12/site-packages/sqlalchemy/orm/query.py\", line 2759, in first\n    return self.limit(1)._iter().first()  # type: ignore\n           ^^^^^^^^^^^^^^^^^^^^^\n  File \"/home/ronin/devops/apibackend/.venv/lib/python3.12/site-packages/sqlalchemy/orm/query.py\", line 2857, in _iter\n    result: Union[ScalarResult[_T], Result[_T]] = self.session.execute(\n                                                  ^^^^^^^^^^^^^^^^^^^^^\n  File \"/home/ronin/devops/apibackend/.venv/lib/python3.12/site-packages/sqlalchemy/orm/session.py\", line 2351, in execute\n    return self._execute_internal(\n           ^^^^^^^^^^^^^^^^^^^^^^^\n  File \"/home/ronin/devops/apibackend/.venv/lib/python3.12/site-packages/sqlalchemy/orm/session.py\", line 2249, in _execute_internal\n    result: Result[Any] = compile_state_cls.orm_execute_statement(\n                          ^^^^^^^^^^^^^^^^^^^^^^^^^^^^^^^^^^^^^^^^\n  File \"/home/ronin/devops/apibackend/.venv/lib/python3.12/site-packages/sqlalchemy/orm/context.py\", line 306, in orm_execute_statement\n    result = conn.execute(\n             ^^^^^^^^^^^^^\n  File \"/home/ronin/devops/apibackend/.venv/lib/python3.12/site-packages/sqlalchemy/engine/base.py\", line 1419, in execute\n    return meth(\n           ^^^^^\n  File \"/home/ronin/devops/apibackend/.venv/lib/python3.12/site-packages/sqlalchemy/sql/elements.py\", line 526, in _execute_on_connection\n    return connection._execute_clauseelement(\n           ^^^^^^^^^^^^^^^^^^^^^^^^^^^^^^^^^^\n  File \"/home/ronin/devops/apibackend/.venv/lib/python3.12/site-packages/sqlalchemy/engine/base.py\", line 1641, in _execute_clauseelement\n    ret = self._execute_context(\n          ^^^^^^^^^^^^^^^^^^^^^^\n  File \"/home/ronin/devops/apibackend/.venv/lib/python3.12/site-packages/sqlalchemy/engine/base.py\", line 1846, in _execute_context\n    return self._exec_single_context(\n           ^^^^^^^^^^^^^^^^^^^^^^^^^^\n  File \"/home/ronin/devops/apibackend/.venv/lib/python3.12/site-packages/sqlalchemy/engine/base.py\", line 1986, in _exec_single_context\n    self._handle_dbapi_exception(\n  File \"/home/ronin/devops/apibackend/.venv/lib/python3.12/site-packages/sqlalchemy/engine/base.py\", line 2355, in _handle_dbapi_exception\n    raise sqlalchemy_exception.with_traceback(exc_info[2]) from e\n  File \"/home/ronin/devops/apibackend/.venv/lib/python3.12/site-packages/sqlalchemy/engine/base.py\", line 1967, in _exec_single_context\n    self.dialect.do_execute(\n  File \"/home/ronin/devops/apibackend/.venv/lib/python3.12/site-packages/sqlalchemy/engine/default.py\", line 951, in do_execute\n    cursor.execute(statement, parameters)\nsqlalchemy.exc.OperationalError: (sqlite3.OperationalError) no such table: users\n[SQL: SELECT users.id AS users_id, users.username AS users_username, users.first_name AS users_first_name, users.last_name AS users_last_name, users.email AS users_email, users.password AS users_password, users.is_active AS users_is_active, users.is_staff AS users_is_staff, users.is_superuser AS users_is_superuser \nFROM users \nWHERE users.email = ?\n LIMIT ? OFFSET ?]\n[parameters: ('loginuser@example.com', 1, 0)]\n(Background on this error at: https://sqlalche.me/e/20/e3q8)"}
{"timestamp": "2025-10-15T23:57:41.504371", "level": "ERROR", "module": "auth", "function": "register", "line": 47, "message": "Error during registration: (sqlite3.OperationalError) no such table: users\n[SQL: SELECT users.id AS users_id, users.username AS users_username, users.first_name AS users_first_name, users.last_name AS users_last_name, users.email AS users_email, users.password AS users_password, users.is_active AS users_is_active, users.is_staff AS users_is_staff, users.is_superuser AS users_is_superuser \nFROM users \nWHERE users.email = ?\n LIMIT ? OFFSET ?]\n[parameters: ('newuser@example.com', 1, 0)]\n(Background on this error at: https://sqlalche.me/e/20/e3q8)", "exception": "Traceback (most recent call last):\n  File \"/home/ronin/devops/apibackend/.venv/lib/python3.12/site-packages/sqlalchemy/engine/base.py\", line 1967, in _exec_single_context\n    self.dialect.do_execute(\n  File \"/home/ronin/devops/apibackend/.venv/lib/python3.12/site-packages/sqlalchemy/engine/default.py\", line 951, in do_execute\n    cursor.execute(statement, parameters)\nsqlite3.OperationalError: no such table: users\n\nThe above exception was the direct cause of the following exception:\n\nTraceback (most recent call last):\n  File \"/home/ronin/devops/apibackend/routers/auth.py\", line 26, in register\n    existing_user = db.query(User).filter(User.email == user.email).first()\n                    ^^^^^^^^^^^^^^^^^^^^^^^^^^^^^^^^^^^^^^^^^^^^^^^^^^^^^^^\n  File \"/home/ronin/devops/apibackend/.venv/lib/python3.12/site-packages/sqlalchemy/orm/query.py\", line 2759, in first\n    return self.limit(1)._iter().first()  # type: ignore\n           ^^^^^^^^^^^^^^^^^^^^^\n  File \"/home/ronin/devops/apibackend/.venv/lib/python3.12/site-packages/sqlalchemy/orm/query.py\", line 2857, in _iter\n    result: Union[ScalarResult[_T], Result[_T]] = self.session.execute(\n                                                  ^^^^^^^^^^^^^^^^^^^^^\n  File \"/home/ronin/devops/apibackend/.venv/lib/python3.12/site-packages/sqlalchemy/orm/session.py\", line 2351, in execute\n    return self._execute_internal(\n           ^^^^^^^^^^^^^^^^^^^^^^^\n  File \"/home/ronin/devops/apibackend/.venv/lib/python3.12/site-packages/sqlalchemy/orm/session.py\", line 2249, in _execute_internal\n    result: Result[Any] = compile_state_cls.orm_execute_statement(\n                          ^^^^^^^^^^^^^^^^^^^^^^^^^^^^^^^^^^^^^^^^\n  File \"/home/ronin/devops/apibackend/.venv/lib/python3.12/site-packages/sqlalchemy/orm/context.py\", line 306, in orm_execute_statement\n    result = conn.execute(\n             ^^^^^^^^^^^^^\n  File \"/home/ronin/devops/apibackend/.venv/lib/python3.12/site-packages/sqlalchemy/engine/base.py\", line 1419, in execute\n    return meth(\n           ^^^^^\n  File \"/home/ronin/devops/apibackend/.venv/lib/python3.12/site-packages/sqlalchemy/sql/elements.py\", line 526, in _execute_on_connection\n    return connection._execute_clauseelement(\n           ^^^^^^^^^^^^^^^^^^^^^^^^^^^^^^^^^^\n  File \"/home/ronin/devops/apibackend/.venv/lib/python3.12/site-packages/sqlalchemy/engine/base.py\", line 1641, in _execute_clauseelement\n    ret = self._execute_context(\n          ^^^^^^^^^^^^^^^^^^^^^^\n  File \"/home/ronin/devops/apibackend/.venv/lib/python3.12/site-packages/sqlalchemy/engine/base.py\", line 1846, in _execute_context\n    return self._exec_single_context(\n           ^^^^^^^^^^^^^^^^^^^^^^^^^^\n  File \"/home/ronin/devops/apibackend/.venv/lib/python3.12/site-packages/sqlalchemy/engine/base.py\", line 1986, in _exec_single_context\n    self._handle_dbapi_exception(\n  File \"/home/ronin/devops/apibackend/.venv/lib/python3.12/site-packages/sqlalchemy/engine/base.py\", line 2355, in _handle_dbapi_exception\n    raise sqlalchemy_exception.with_traceback(exc_info[2]) from e\n  File \"/home/ronin/devops/apibackend/.venv/lib/python3.12/site-packages/sqlalchemy/engine/base.py\", line 1967, in _exec_single_context\n    self.dialect.do_execute(\n  File \"/home/ronin/devops/apibackend/.venv/lib/python3.12/site-packages/sqlalchemy/engine/default.py\", line 951, in do_execute\n    cursor.execute(statement, parameters)\nsqlalchemy.exc.OperationalError: (sqlite3.OperationalError) no such table: users\n[SQL: SELECT users.id AS users_id, users.username AS users_username, users.first_name AS users_first_name, users.last_name AS users_last_name, users.email AS users_email, users.password AS users_password, users.is_active AS users_is_active, users.is_staff AS users_is_staff, users.is_superuser AS users_is_superuser \nFROM users \nWHERE users.email = ?\n LIMIT ? OFFSET ?]\n[parameters: ('newuser@example.com', 1, 0)]\n(Background on this error at: https://sqlalche.me/e/20/e3q8)"}
{"timestamp": "2025-10-15T23:57:41.531551", "level": "ERROR", "module": "auth", "function": "register", "line": 47, "message": "Error during registration: (sqlite3.OperationalError) no such table: users\n[SQL: SELECT users.id AS users_id, users.username AS users_username, users.first_name AS users_first_name, users.last_name AS users_last_name, users.email AS users_email, users.password AS users_password, users.is_active AS users_is_active, users.is_staff AS users_is_staff, users.is_superuser AS users_is_superuser \nFROM users \nWHERE users.email = ?\n LIMIT ? OFFSET ?]\n[parameters: ('duplicate@example.com', 1, 0)]\n(Background on this error at: https://sqlalche.me/e/20/e3q8)", "exception": "Traceback (most recent call last):\n  File \"/home/ronin/devops/apibackend/.venv/lib/python3.12/site-packages/sqlalchemy/engine/base.py\", line 1967, in _exec_single_context\n    self.dialect.do_execute(\n  File \"/home/ronin/devops/apibackend/.venv/lib/python3.12/site-packages/sqlalchemy/engine/default.py\", line 951, in do_execute\n    cursor.execute(statement, parameters)\nsqlite3.OperationalError: no such table: users\n\nThe above exception was the direct cause of the following exception:\n\nTraceback (most recent call last):\n  File \"/home/ronin/devops/apibackend/routers/auth.py\", line 26, in register\n    existing_user = db.query(User).filter(User.email == user.email).first()\n                    ^^^^^^^^^^^^^^^^^^^^^^^^^^^^^^^^^^^^^^^^^^^^^^^^^^^^^^^\n  File \"/home/ronin/devops/apibackend/.venv/lib/python3.12/site-packages/sqlalchemy/orm/query.py\", line 2759, in first\n    return self.limit(1)._iter().first()  # type: ignore\n           ^^^^^^^^^^^^^^^^^^^^^\n  File \"/home/ronin/devops/apibackend/.venv/lib/python3.12/site-packages/sqlalchemy/orm/query.py\", line 2857, in _iter\n    result: Union[ScalarResult[_T], Result[_T]] = self.session.execute(\n                                                  ^^^^^^^^^^^^^^^^^^^^^\n  File \"/home/ronin/devops/apibackend/.venv/lib/python3.12/site-packages/sqlalchemy/orm/session.py\", line 2351, in execute\n    return self._execute_internal(\n           ^^^^^^^^^^^^^^^^^^^^^^^\n  File \"/home/ronin/devops/apibackend/.venv/lib/python3.12/site-packages/sqlalchemy/orm/session.py\", line 2249, in _execute_internal\n    result: Result[Any] = compile_state_cls.orm_execute_statement(\n                          ^^^^^^^^^^^^^^^^^^^^^^^^^^^^^^^^^^^^^^^^\n  File \"/home/ronin/devops/apibackend/.venv/lib/python3.12/site-packages/sqlalchemy/orm/context.py\", line 306, in orm_execute_statement\n    result = conn.execute(\n             ^^^^^^^^^^^^^\n  File \"/home/ronin/devops/apibackend/.venv/lib/python3.12/site-packages/sqlalchemy/engine/base.py\", line 1419, in execute\n    return meth(\n           ^^^^^\n  File \"/home/ronin/devops/apibackend/.venv/lib/python3.12/site-packages/sqlalchemy/sql/elements.py\", line 526, in _execute_on_connection\n    return connection._execute_clauseelement(\n           ^^^^^^^^^^^^^^^^^^^^^^^^^^^^^^^^^^\n  File \"/home/ronin/devops/apibackend/.venv/lib/python3.12/site-packages/sqlalchemy/engine/base.py\", line 1641, in _execute_clauseelement\n    ret = self._execute_context(\n          ^^^^^^^^^^^^^^^^^^^^^^\n  File \"/home/ronin/devops/apibackend/.venv/lib/python3.12/site-packages/sqlalchemy/engine/base.py\", line 1846, in _execute_context\n    return self._exec_single_context(\n           ^^^^^^^^^^^^^^^^^^^^^^^^^^\n  File \"/home/ronin/devops/apibackend/.venv/lib/python3.12/site-packages/sqlalchemy/engine/base.py\", line 1986, in _exec_single_context\n    self._handle_dbapi_exception(\n  File \"/home/ronin/devops/apibackend/.venv/lib/python3.12/site-packages/sqlalchemy/engine/base.py\", line 2355, in _handle_dbapi_exception\n    raise sqlalchemy_exception.with_traceback(exc_info[2]) from e\n  File \"/home/ronin/devops/apibackend/.venv/lib/python3.12/site-packages/sqlalchemy/engine/base.py\", line 1967, in _exec_single_context\n    self.dialect.do_execute(\n  File \"/home/ronin/devops/apibackend/.venv/lib/python3.12/site-packages/sqlalchemy/engine/default.py\", line 951, in do_execute\n    cursor.execute(statement, parameters)\nsqlalchemy.exc.OperationalError: (sqlite3.OperationalError) no such table: users\n[SQL: SELECT users.id AS users_id, users.username AS users_username, users.first_name AS users_first_name, users.last_name AS users_last_name, users.email AS users_email, users.password AS users_password, users.is_active AS users_is_active, users.is_staff AS users_is_staff, users.is_superuser AS users_is_superuser \nFROM users \nWHERE users.email = ?\n LIMIT ? OFFSET ?]\n[parameters: ('duplicate@example.com', 1, 0)]\n(Background on this error at: https://sqlalche.me/e/20/e3q8)"}
{"timestamp": "2025-10-15T23:57:41.537499", "level": "ERROR", "module": "auth", "function": "register", "line": 47, "message": "Error during registration: (sqlite3.OperationalError) no such table: users\n[SQL: SELECT users.id AS users_id, users.username AS users_username, users.first_name AS users_first_name, users.last_name AS users_last_name, users.email AS users_email, users.password AS users_password, users.is_active AS users_is_active, users.is_staff AS users_is_staff, users.is_superuser AS users_is_superuser \nFROM users \nWHERE users.email = ?\n LIMIT ? OFFSET ?]\n[parameters: ('duplicate2@example.com', 1, 0)]\n(Background on this error at: https://sqlalche.me/e/20/e3q8)", "exception": "Traceback (most recent call last):\n  File \"/home/ronin/devops/apibackend/.venv/lib/python3.12/site-packages/sqlalchemy/engine/base.py\", line 1967, in _exec_single_context\n    self.dialect.do_execute(\n  File \"/home/ronin/devops/apibackend/.venv/lib/python3.12/site-packages/sqlalchemy/engine/default.py\", line 951, in do_execute\n    cursor.execute(statement, parameters)\nsqlite3.OperationalError: no such table: users\n\nThe above exception was the direct cause of the following exception:\n\nTraceback (most recent call last):\n  File \"/home/ronin/devops/apibackend/routers/auth.py\", line 26, in register\n    existing_user = db.query(User).filter(User.email == user.email).first()\n                    ^^^^^^^^^^^^^^^^^^^^^^^^^^^^^^^^^^^^^^^^^^^^^^^^^^^^^^^\n  File \"/home/ronin/devops/apibackend/.venv/lib/python3.12/site-packages/sqlalchemy/orm/query.py\", line 2759, in first\n    return self.limit(1)._iter().first()  # type: ignore\n           ^^^^^^^^^^^^^^^^^^^^^\n  File \"/home/ronin/devops/apibackend/.venv/lib/python3.12/site-packages/sqlalchemy/orm/query.py\", line 2857, in _iter\n    result: Union[ScalarResult[_T], Result[_T]] = self.session.execute(\n                                                  ^^^^^^^^^^^^^^^^^^^^^\n  File \"/home/ronin/devops/apibackend/.venv/lib/python3.12/site-packages/sqlalchemy/orm/session.py\", line 2351, in execute\n    return self._execute_internal(\n           ^^^^^^^^^^^^^^^^^^^^^^^\n  File \"/home/ronin/devops/apibackend/.venv/lib/python3.12/site-packages/sqlalchemy/orm/session.py\", line 2249, in _execute_internal\n    result: Result[Any] = compile_state_cls.orm_execute_statement(\n                          ^^^^^^^^^^^^^^^^^^^^^^^^^^^^^^^^^^^^^^^^\n  File \"/home/ronin/devops/apibackend/.venv/lib/python3.12/site-packages/sqlalchemy/orm/context.py\", line 306, in orm_execute_statement\n    result = conn.execute(\n             ^^^^^^^^^^^^^\n  File \"/home/ronin/devops/apibackend/.venv/lib/python3.12/site-packages/sqlalchemy/engine/base.py\", line 1419, in execute\n    return meth(\n           ^^^^^\n  File \"/home/ronin/devops/apibackend/.venv/lib/python3.12/site-packages/sqlalchemy/sql/elements.py\", line 526, in _execute_on_connection\n    return connection._execute_clauseelement(\n           ^^^^^^^^^^^^^^^^^^^^^^^^^^^^^^^^^^\n  File \"/home/ronin/devops/apibackend/.venv/lib/python3.12/site-packages/sqlalchemy/engine/base.py\", line 1641, in _execute_clauseelement\n    ret = self._execute_context(\n          ^^^^^^^^^^^^^^^^^^^^^^\n  File \"/home/ronin/devops/apibackend/.venv/lib/python3.12/site-packages/sqlalchemy/engine/base.py\", line 1846, in _execute_context\n    return self._exec_single_context(\n           ^^^^^^^^^^^^^^^^^^^^^^^^^^\n  File \"/home/ronin/devops/apibackend/.venv/lib/python3.12/site-packages/sqlalchemy/engine/base.py\", line 1986, in _exec_single_context\n    self._handle_dbapi_exception(\n  File \"/home/ronin/devops/apibackend/.venv/lib/python3.12/site-packages/sqlalchemy/engine/base.py\", line 2355, in _handle_dbapi_exception\n    raise sqlalchemy_exception.with_traceback(exc_info[2]) from e\n  File \"/home/ronin/devops/apibackend/.venv/lib/python3.12/site-packages/sqlalchemy/engine/base.py\", line 1967, in _exec_single_context\n    self.dialect.do_execute(\n  File \"/home/ronin/devops/apibackend/.venv/lib/python3.12/site-packages/sqlalchemy/engine/default.py\", line 951, in do_execute\n    cursor.execute(statement, parameters)\nsqlalchemy.exc.OperationalError: (sqlite3.OperationalError) no such table: users\n[SQL: SELECT users.id AS users_id, users.username AS users_username, users.first_name AS users_first_name, users.last_name AS users_last_name, users.email AS users_email, users.password AS users_password, users.is_active AS users_is_active, users.is_staff AS users_is_staff, users.is_superuser AS users_is_superuser \nFROM users \nWHERE users.email = ?\n LIMIT ? OFFSET ?]\n[parameters: ('duplicate2@example.com', 1, 0)]\n(Background on this error at: https://sqlalche.me/e/20/e3q8)"}
{"timestamp": "2025-10-15T23:57:41.544387", "level": "ERROR", "module": "auth", "function": "register", "line": 47, "message": "Error during registration: (sqlite3.OperationalError) no such table: users\n[SQL: SELECT users.id AS users_id, users.username AS users_username, users.first_name AS users_first_name, users.last_name AS users_last_name, users.email AS users_email, users.password AS users_password, users.is_active AS users_is_active, users.is_staff AS users_is_staff, users.is_superuser AS users_is_superuser \nFROM users \nWHERE users.email = ?\n LIMIT ? OFFSET ?]\n[parameters: ('loginuser@example.com', 1, 0)]\n(Background on this error at: https://sqlalche.me/e/20/e3q8)", "exception": "Traceback (most recent call last):\n  File \"/home/ronin/devops/apibackend/.venv/lib/python3.12/site-packages/sqlalchemy/engine/base.py\", line 1967, in _exec_single_context\n    self.dialect.do_execute(\n  File \"/home/ronin/devops/apibackend/.venv/lib/python3.12/site-packages/sqlalchemy/engine/default.py\", line 951, in do_execute\n    cursor.execute(statement, parameters)\nsqlite3.OperationalError: no such table: users\n\nThe above exception was the direct cause of the following exception:\n\nTraceback (most recent call last):\n  File \"/home/ronin/devops/apibackend/routers/auth.py\", line 26, in register\n    existing_user = db.query(User).filter(User.email == user.email).first()\n                    ^^^^^^^^^^^^^^^^^^^^^^^^^^^^^^^^^^^^^^^^^^^^^^^^^^^^^^^\n  File \"/home/ronin/devops/apibackend/.venv/lib/python3.12/site-packages/sqlalchemy/orm/query.py\", line 2759, in first\n    return self.limit(1)._iter().first()  # type: ignore\n           ^^^^^^^^^^^^^^^^^^^^^\n  File \"/home/ronin/devops/apibackend/.venv/lib/python3.12/site-packages/sqlalchemy/orm/query.py\", line 2857, in _iter\n    result: Union[ScalarResult[_T], Result[_T]] = self.session.execute(\n                                                  ^^^^^^^^^^^^^^^^^^^^^\n  File \"/home/ronin/devops/apibackend/.venv/lib/python3.12/site-packages/sqlalchemy/orm/session.py\", line 2351, in execute\n    return self._execute_internal(\n           ^^^^^^^^^^^^^^^^^^^^^^^\n  File \"/home/ronin/devops/apibackend/.venv/lib/python3.12/site-packages/sqlalchemy/orm/session.py\", line 2249, in _execute_internal\n    result: Result[Any] = compile_state_cls.orm_execute_statement(\n                          ^^^^^^^^^^^^^^^^^^^^^^^^^^^^^^^^^^^^^^^^\n  File \"/home/ronin/devops/apibackend/.venv/lib/python3.12/site-packages/sqlalchemy/orm/context.py\", line 306, in orm_execute_statement\n    result = conn.execute(\n             ^^^^^^^^^^^^^\n  File \"/home/ronin/devops/apibackend/.venv/lib/python3.12/site-packages/sqlalchemy/engine/base.py\", line 1419, in execute\n    return meth(\n           ^^^^^\n  File \"/home/ronin/devops/apibackend/.venv/lib/python3.12/site-packages/sqlalchemy/sql/elements.py\", line 526, in _execute_on_connection\n    return connection._execute_clauseelement(\n           ^^^^^^^^^^^^^^^^^^^^^^^^^^^^^^^^^^\n  File \"/home/ronin/devops/apibackend/.venv/lib/python3.12/site-packages/sqlalchemy/engine/base.py\", line 1641, in _execute_clauseelement\n    ret = self._execute_context(\n          ^^^^^^^^^^^^^^^^^^^^^^\n  File \"/home/ronin/devops/apibackend/.venv/lib/python3.12/site-packages/sqlalchemy/engine/base.py\", line 1846, in _execute_context\n    return self._exec_single_context(\n           ^^^^^^^^^^^^^^^^^^^^^^^^^^\n  File \"/home/ronin/devops/apibackend/.venv/lib/python3.12/site-packages/sqlalchemy/engine/base.py\", line 1986, in _exec_single_context\n    self._handle_dbapi_exception(\n  File \"/home/ronin/devops/apibackend/.venv/lib/python3.12/site-packages/sqlalchemy/engine/base.py\", line 2355, in _handle_dbapi_exception\n    raise sqlalchemy_exception.with_traceback(exc_info[2]) from e\n  File \"/home/ronin/devops/apibackend/.venv/lib/python3.12/site-packages/sqlalchemy/engine/base.py\", line 1967, in _exec_single_context\n    self.dialect.do_execute(\n  File \"/home/ronin/devops/apibackend/.venv/lib/python3.12/site-packages/sqlalchemy/engine/default.py\", line 951, in do_execute\n    cursor.execute(statement, parameters)\nsqlalchemy.exc.OperationalError: (sqlite3.OperationalError) no such table: users\n[SQL: SELECT users.id AS users_id, users.username AS users_username, users.first_name AS users_first_name, users.last_name AS users_last_name, users.email AS users_email, users.password AS users_password, users.is_active AS users_is_active, users.is_staff AS users_is_staff, users.is_superuser AS users_is_superuser \nFROM users \nWHERE users.email = ?\n LIMIT ? OFFSET ?]\n[parameters: ('loginuser@example.com', 1, 0)]\n(Background on this error at: https://sqlalche.me/e/20/e3q8)"}
{"timestamp": "2025-10-16T00:05:23.098814", "level": "ERROR", "module": "auth", "function": "register", "line": 47, "message": "Error during registration: (sqlite3.OperationalError) no such table: users\n[SQL: SELECT users.id AS users_id, users.username AS users_username, users.first_name AS users_first_name, users.last_name AS users_last_name, users.email AS users_email, users.password AS users_password, users.is_active AS users_is_active, users.is_staff AS users_is_staff, users.is_superuser AS users_is_superuser \nFROM users \nWHERE users.email = ?\n LIMIT ? OFFSET ?]\n[parameters: ('newuser@example.com', 1, 0)]\n(Background on this error at: https://sqlalche.me/e/20/e3q8)", "exception": "Traceback (most recent call last):\n  File \"/home/ronin/devops/apibackend/.venv/lib/python3.12/site-packages/sqlalchemy/engine/base.py\", line 1967, in _exec_single_context\n    self.dialect.do_execute(\n  File \"/home/ronin/devops/apibackend/.venv/lib/python3.12/site-packages/sqlalchemy/engine/default.py\", line 951, in do_execute\n    cursor.execute(statement, parameters)\nsqlite3.OperationalError: no such table: users\n\nThe above exception was the direct cause of the following exception:\n\nTraceback (most recent call last):\n  File \"/home/ronin/devops/apibackend/routers/auth.py\", line 26, in register\n    existing_user = db.query(User).filter(User.email == user.email).first()\n                    ^^^^^^^^^^^^^^^^^^^^^^^^^^^^^^^^^^^^^^^^^^^^^^^^^^^^^^^\n  File \"/home/ronin/devops/apibackend/.venv/lib/python3.12/site-packages/sqlalchemy/orm/query.py\", line 2759, in first\n    return self.limit(1)._iter().first()  # type: ignore\n           ^^^^^^^^^^^^^^^^^^^^^\n  File \"/home/ronin/devops/apibackend/.venv/lib/python3.12/site-packages/sqlalchemy/orm/query.py\", line 2857, in _iter\n    result: Union[ScalarResult[_T], Result[_T]] = self.session.execute(\n                                                  ^^^^^^^^^^^^^^^^^^^^^\n  File \"/home/ronin/devops/apibackend/.venv/lib/python3.12/site-packages/sqlalchemy/orm/session.py\", line 2351, in execute\n    return self._execute_internal(\n           ^^^^^^^^^^^^^^^^^^^^^^^\n  File \"/home/ronin/devops/apibackend/.venv/lib/python3.12/site-packages/sqlalchemy/orm/session.py\", line 2249, in _execute_internal\n    result: Result[Any] = compile_state_cls.orm_execute_statement(\n                          ^^^^^^^^^^^^^^^^^^^^^^^^^^^^^^^^^^^^^^^^\n  File \"/home/ronin/devops/apibackend/.venv/lib/python3.12/site-packages/sqlalchemy/orm/context.py\", line 306, in orm_execute_statement\n    result = conn.execute(\n             ^^^^^^^^^^^^^\n  File \"/home/ronin/devops/apibackend/.venv/lib/python3.12/site-packages/sqlalchemy/engine/base.py\", line 1419, in execute\n    return meth(\n           ^^^^^\n  File \"/home/ronin/devops/apibackend/.venv/lib/python3.12/site-packages/sqlalchemy/sql/elements.py\", line 526, in _execute_on_connection\n    return connection._execute_clauseelement(\n           ^^^^^^^^^^^^^^^^^^^^^^^^^^^^^^^^^^\n  File \"/home/ronin/devops/apibackend/.venv/lib/python3.12/site-packages/sqlalchemy/engine/base.py\", line 1641, in _execute_clauseelement\n    ret = self._execute_context(\n          ^^^^^^^^^^^^^^^^^^^^^^\n  File \"/home/ronin/devops/apibackend/.venv/lib/python3.12/site-packages/sqlalchemy/engine/base.py\", line 1846, in _execute_context\n    return self._exec_single_context(\n           ^^^^^^^^^^^^^^^^^^^^^^^^^^\n  File \"/home/ronin/devops/apibackend/.venv/lib/python3.12/site-packages/sqlalchemy/engine/base.py\", line 1986, in _exec_single_context\n    self._handle_dbapi_exception(\n  File \"/home/ronin/devops/apibackend/.venv/lib/python3.12/site-packages/sqlalchemy/engine/base.py\", line 2355, in _handle_dbapi_exception\n    raise sqlalchemy_exception.with_traceback(exc_info[2]) from e\n  File \"/home/ronin/devops/apibackend/.venv/lib/python3.12/site-packages/sqlalchemy/engine/base.py\", line 1967, in _exec_single_context\n    self.dialect.do_execute(\n  File \"/home/ronin/devops/apibackend/.venv/lib/python3.12/site-packages/sqlalchemy/engine/default.py\", line 951, in do_execute\n    cursor.execute(statement, parameters)\nsqlalchemy.exc.OperationalError: (sqlite3.OperationalError) no such table: users\n[SQL: SELECT users.id AS users_id, users.username AS users_username, users.first_name AS users_first_name, users.last_name AS users_last_name, users.email AS users_email, users.password AS users_password, users.is_active AS users_is_active, users.is_staff AS users_is_staff, users.is_superuser AS users_is_superuser \nFROM users \nWHERE users.email = ?\n LIMIT ? OFFSET ?]\n[parameters: ('newuser@example.com', 1, 0)]\n(Background on this error at: https://sqlalche.me/e/20/e3q8)"}
{"timestamp": "2025-10-16T00:05:23.128040", "level": "ERROR", "module": "auth", "function": "register", "line": 47, "message": "Error during registration: (sqlite3.OperationalError) no such table: users\n[SQL: SELECT users.id AS users_id, users.username AS users_username, users.first_name AS users_first_name, users.last_name AS users_last_name, users.email AS users_email, users.password AS users_password, users.is_active AS users_is_active, users.is_staff AS users_is_staff, users.is_superuser AS users_is_superuser \nFROM users \nWHERE users.email = ?\n LIMIT ? OFFSET ?]\n[parameters: ('duplicate@example.com', 1, 0)]\n(Background on this error at: https://sqlalche.me/e/20/e3q8)", "exception": "Traceback (most recent call last):\n  File \"/home/ronin/devops/apibackend/.venv/lib/python3.12/site-packages/sqlalchemy/engine/base.py\", line 1967, in _exec_single_context\n    self.dialect.do_execute(\n  File \"/home/ronin/devops/apibackend/.venv/lib/python3.12/site-packages/sqlalchemy/engine/default.py\", line 951, in do_execute\n    cursor.execute(statement, parameters)\nsqlite3.OperationalError: no such table: users\n\nThe above exception was the direct cause of the following exception:\n\nTraceback (most recent call last):\n  File \"/home/ronin/devops/apibackend/routers/auth.py\", line 26, in register\n    existing_user = db.query(User).filter(User.email == user.email).first()\n                    ^^^^^^^^^^^^^^^^^^^^^^^^^^^^^^^^^^^^^^^^^^^^^^^^^^^^^^^\n  File \"/home/ronin/devops/apibackend/.venv/lib/python3.12/site-packages/sqlalchemy/orm/query.py\", line 2759, in first\n    return self.limit(1)._iter().first()  # type: ignore\n           ^^^^^^^^^^^^^^^^^^^^^\n  File \"/home/ronin/devops/apibackend/.venv/lib/python3.12/site-packages/sqlalchemy/orm/query.py\", line 2857, in _iter\n    result: Union[ScalarResult[_T], Result[_T]] = self.session.execute(\n                                                  ^^^^^^^^^^^^^^^^^^^^^\n  File \"/home/ronin/devops/apibackend/.venv/lib/python3.12/site-packages/sqlalchemy/orm/session.py\", line 2351, in execute\n    return self._execute_internal(\n           ^^^^^^^^^^^^^^^^^^^^^^^\n  File \"/home/ronin/devops/apibackend/.venv/lib/python3.12/site-packages/sqlalchemy/orm/session.py\", line 2249, in _execute_internal\n    result: Result[Any] = compile_state_cls.orm_execute_statement(\n                          ^^^^^^^^^^^^^^^^^^^^^^^^^^^^^^^^^^^^^^^^\n  File \"/home/ronin/devops/apibackend/.venv/lib/python3.12/site-packages/sqlalchemy/orm/context.py\", line 306, in orm_execute_statement\n    result = conn.execute(\n             ^^^^^^^^^^^^^\n  File \"/home/ronin/devops/apibackend/.venv/lib/python3.12/site-packages/sqlalchemy/engine/base.py\", line 1419, in execute\n    return meth(\n           ^^^^^\n  File \"/home/ronin/devops/apibackend/.venv/lib/python3.12/site-packages/sqlalchemy/sql/elements.py\", line 526, in _execute_on_connection\n    return connection._execute_clauseelement(\n           ^^^^^^^^^^^^^^^^^^^^^^^^^^^^^^^^^^\n  File \"/home/ronin/devops/apibackend/.venv/lib/python3.12/site-packages/sqlalchemy/engine/base.py\", line 1641, in _execute_clauseelement\n    ret = self._execute_context(\n          ^^^^^^^^^^^^^^^^^^^^^^\n  File \"/home/ronin/devops/apibackend/.venv/lib/python3.12/site-packages/sqlalchemy/engine/base.py\", line 1846, in _execute_context\n    return self._exec_single_context(\n           ^^^^^^^^^^^^^^^^^^^^^^^^^^\n  File \"/home/ronin/devops/apibackend/.venv/lib/python3.12/site-packages/sqlalchemy/engine/base.py\", line 1986, in _exec_single_context\n    self._handle_dbapi_exception(\n  File \"/home/ronin/devops/apibackend/.venv/lib/python3.12/site-packages/sqlalchemy/engine/base.py\", line 2355, in _handle_dbapi_exception\n    raise sqlalchemy_exception.with_traceback(exc_info[2]) from e\n  File \"/home/ronin/devops/apibackend/.venv/lib/python3.12/site-packages/sqlalchemy/engine/base.py\", line 1967, in _exec_single_context\n    self.dialect.do_execute(\n  File \"/home/ronin/devops/apibackend/.venv/lib/python3.12/site-packages/sqlalchemy/engine/default.py\", line 951, in do_execute\n    cursor.execute(statement, parameters)\nsqlalchemy.exc.OperationalError: (sqlite3.OperationalError) no such table: users\n[SQL: SELECT users.id AS users_id, users.username AS users_username, users.first_name AS users_first_name, users.last_name AS users_last_name, users.email AS users_email, users.password AS users_password, users.is_active AS users_is_active, users.is_staff AS users_is_staff, users.is_superuser AS users_is_superuser \nFROM users \nWHERE users.email = ?\n LIMIT ? OFFSET ?]\n[parameters: ('duplicate@example.com', 1, 0)]\n(Background on this error at: https://sqlalche.me/e/20/e3q8)"}
{"timestamp": "2025-10-16T00:05:23.132127", "level": "ERROR", "module": "auth", "function": "register", "line": 47, "message": "Error during registration: (sqlite3.OperationalError) no such table: users\n[SQL: SELECT users.id AS users_id, users.username AS users_username, users.first_name AS users_first_name, users.last_name AS users_last_name, users.email AS users_email, users.password AS users_password, users.is_active AS users_is_active, users.is_staff AS users_is_staff, users.is_superuser AS users_is_superuser \nFROM users \nWHERE users.email = ?\n LIMIT ? OFFSET ?]\n[parameters: ('duplicate@example.com', 1, 0)]\n(Background on this error at: https://sqlalche.me/e/20/e3q8)", "exception": "Traceback (most recent call last):\n  File \"/home/ronin/devops/apibackend/.venv/lib/python3.12/site-packages/sqlalchemy/engine/base.py\", line 1967, in _exec_single_context\n    self.dialect.do_execute(\n  File \"/home/ronin/devops/apibackend/.venv/lib/python3.12/site-packages/sqlalchemy/engine/default.py\", line 951, in do_execute\n    cursor.execute(statement, parameters)\nsqlite3.OperationalError: no such table: users\n\nThe above exception was the direct cause of the following exception:\n\nTraceback (most recent call last):\n  File \"/home/ronin/devops/apibackend/routers/auth.py\", line 26, in register\n    existing_user = db.query(User).filter(User.email == user.email).first()\n                    ^^^^^^^^^^^^^^^^^^^^^^^^^^^^^^^^^^^^^^^^^^^^^^^^^^^^^^^\n  File \"/home/ronin/devops/apibackend/.venv/lib/python3.12/site-packages/sqlalchemy/orm/query.py\", line 2759, in first\n    return self.limit(1)._iter().first()  # type: ignore\n           ^^^^^^^^^^^^^^^^^^^^^\n  File \"/home/ronin/devops/apibackend/.venv/lib/python3.12/site-packages/sqlalchemy/orm/query.py\", line 2857, in _iter\n    result: Union[ScalarResult[_T], Result[_T]] = self.session.execute(\n                                                  ^^^^^^^^^^^^^^^^^^^^^\n  File \"/home/ronin/devops/apibackend/.venv/lib/python3.12/site-packages/sqlalchemy/orm/session.py\", line 2351, in execute\n    return self._execute_internal(\n           ^^^^^^^^^^^^^^^^^^^^^^^\n  File \"/home/ronin/devops/apibackend/.venv/lib/python3.12/site-packages/sqlalchemy/orm/session.py\", line 2249, in _execute_internal\n    result: Result[Any] = compile_state_cls.orm_execute_statement(\n                          ^^^^^^^^^^^^^^^^^^^^^^^^^^^^^^^^^^^^^^^^\n  File \"/home/ronin/devops/apibackend/.venv/lib/python3.12/site-packages/sqlalchemy/orm/context.py\", line 306, in orm_execute_statement\n    result = conn.execute(\n             ^^^^^^^^^^^^^\n  File \"/home/ronin/devops/apibackend/.venv/lib/python3.12/site-packages/sqlalchemy/engine/base.py\", line 1419, in execute\n    return meth(\n           ^^^^^\n  File \"/home/ronin/devops/apibackend/.venv/lib/python3.12/site-packages/sqlalchemy/sql/elements.py\", line 526, in _execute_on_connection\n    return connection._execute_clauseelement(\n           ^^^^^^^^^^^^^^^^^^^^^^^^^^^^^^^^^^\n  File \"/home/ronin/devops/apibackend/.venv/lib/python3.12/site-packages/sqlalchemy/engine/base.py\", line 1641, in _execute_clauseelement\n    ret = self._execute_context(\n          ^^^^^^^^^^^^^^^^^^^^^^\n  File \"/home/ronin/devops/apibackend/.venv/lib/python3.12/site-packages/sqlalchemy/engine/base.py\", line 1846, in _execute_context\n    return self._exec_single_context(\n           ^^^^^^^^^^^^^^^^^^^^^^^^^^\n  File \"/home/ronin/devops/apibackend/.venv/lib/python3.12/site-packages/sqlalchemy/engine/base.py\", line 1986, in _exec_single_context\n    self._handle_dbapi_exception(\n  File \"/home/ronin/devops/apibackend/.venv/lib/python3.12/site-packages/sqlalchemy/engine/base.py\", line 2355, in _handle_dbapi_exception\n    raise sqlalchemy_exception.with_traceback(exc_info[2]) from e\n  File \"/home/ronin/devops/apibackend/.venv/lib/python3.12/site-packages/sqlalchemy/engine/base.py\", line 1967, in _exec_single_context\n    self.dialect.do_execute(\n  File \"/home/ronin/devops/apibackend/.venv/lib/python3.12/site-packages/sqlalchemy/engine/default.py\", line 951, in do_execute\n    cursor.execute(statement, parameters)\nsqlalchemy.exc.OperationalError: (sqlite3.OperationalError) no such table: users\n[SQL: SELECT users.id AS users_id, users.username AS users_username, users.first_name AS users_first_name, users.last_name AS users_last_name, users.email AS users_email, users.password AS users_password, users.is_active AS users_is_active, users.is_staff AS users_is_staff, users.is_superuser AS users_is_superuser \nFROM users \nWHERE users.email = ?\n LIMIT ? OFFSET ?]\n[parameters: ('duplicate@example.com', 1, 0)]\n(Background on this error at: https://sqlalche.me/e/20/e3q8)"}
{"timestamp": "2025-10-16T00:05:23.138878", "level": "ERROR", "module": "auth", "function": "register", "line": 47, "message": "Error during registration: (sqlite3.OperationalError) no such table: users\n[SQL: SELECT users.id AS users_id, users.username AS users_username, users.first_name AS users_first_name, users.last_name AS users_last_name, users.email AS users_email, users.password AS users_password, users.is_active AS users_is_active, users.is_staff AS users_is_staff, users.is_superuser AS users_is_superuser \nFROM users \nWHERE users.email = ?\n LIMIT ? OFFSET ?]\n[parameters: ('loginuser@example.com', 1, 0)]\n(Background on this error at: https://sqlalche.me/e/20/e3q8)", "exception": "Traceback (most recent call last):\n  File \"/home/ronin/devops/apibackend/.venv/lib/python3.12/site-packages/sqlalchemy/engine/base.py\", line 1967, in _exec_single_context\n    self.dialect.do_execute(\n  File \"/home/ronin/devops/apibackend/.venv/lib/python3.12/site-packages/sqlalchemy/engine/default.py\", line 951, in do_execute\n    cursor.execute(statement, parameters)\nsqlite3.OperationalError: no such table: users\n\nThe above exception was the direct cause of the following exception:\n\nTraceback (most recent call last):\n  File \"/home/ronin/devops/apibackend/routers/auth.py\", line 26, in register\n    existing_user = db.query(User).filter(User.email == user.email).first()\n                    ^^^^^^^^^^^^^^^^^^^^^^^^^^^^^^^^^^^^^^^^^^^^^^^^^^^^^^^\n  File \"/home/ronin/devops/apibackend/.venv/lib/python3.12/site-packages/sqlalchemy/orm/query.py\", line 2759, in first\n    return self.limit(1)._iter().first()  # type: ignore\n           ^^^^^^^^^^^^^^^^^^^^^\n  File \"/home/ronin/devops/apibackend/.venv/lib/python3.12/site-packages/sqlalchemy/orm/query.py\", line 2857, in _iter\n    result: Union[ScalarResult[_T], Result[_T]] = self.session.execute(\n                                                  ^^^^^^^^^^^^^^^^^^^^^\n  File \"/home/ronin/devops/apibackend/.venv/lib/python3.12/site-packages/sqlalchemy/orm/session.py\", line 2351, in execute\n    return self._execute_internal(\n           ^^^^^^^^^^^^^^^^^^^^^^^\n  File \"/home/ronin/devops/apibackend/.venv/lib/python3.12/site-packages/sqlalchemy/orm/session.py\", line 2249, in _execute_internal\n    result: Result[Any] = compile_state_cls.orm_execute_statement(\n                          ^^^^^^^^^^^^^^^^^^^^^^^^^^^^^^^^^^^^^^^^\n  File \"/home/ronin/devops/apibackend/.venv/lib/python3.12/site-packages/sqlalchemy/orm/context.py\", line 306, in orm_execute_statement\n    result = conn.execute(\n             ^^^^^^^^^^^^^\n  File \"/home/ronin/devops/apibackend/.venv/lib/python3.12/site-packages/sqlalchemy/engine/base.py\", line 1419, in execute\n    return meth(\n           ^^^^^\n  File \"/home/ronin/devops/apibackend/.venv/lib/python3.12/site-packages/sqlalchemy/sql/elements.py\", line 526, in _execute_on_connection\n    return connection._execute_clauseelement(\n           ^^^^^^^^^^^^^^^^^^^^^^^^^^^^^^^^^^\n  File \"/home/ronin/devops/apibackend/.venv/lib/python3.12/site-packages/sqlalchemy/engine/base.py\", line 1641, in _execute_clauseelement\n    ret = self._execute_context(\n          ^^^^^^^^^^^^^^^^^^^^^^\n  File \"/home/ronin/devops/apibackend/.venv/lib/python3.12/site-packages/sqlalchemy/engine/base.py\", line 1846, in _execute_context\n    return self._exec_single_context(\n           ^^^^^^^^^^^^^^^^^^^^^^^^^^\n  File \"/home/ronin/devops/apibackend/.venv/lib/python3.12/site-packages/sqlalchemy/engine/base.py\", line 1986, in _exec_single_context\n    self._handle_dbapi_exception(\n  File \"/home/ronin/devops/apibackend/.venv/lib/python3.12/site-packages/sqlalchemy/engine/base.py\", line 2355, in _handle_dbapi_exception\n    raise sqlalchemy_exception.with_traceback(exc_info[2]) from e\n  File \"/home/ronin/devops/apibackend/.venv/lib/python3.12/site-packages/sqlalchemy/engine/base.py\", line 1967, in _exec_single_context\n    self.dialect.do_execute(\n  File \"/home/ronin/devops/apibackend/.venv/lib/python3.12/site-packages/sqlalchemy/engine/default.py\", line 951, in do_execute\n    cursor.execute(statement, parameters)\nsqlalchemy.exc.OperationalError: (sqlite3.OperationalError) no such table: users\n[SQL: SELECT users.id AS users_id, users.username AS users_username, users.first_name AS users_first_name, users.last_name AS users_last_name, users.email AS users_email, users.password AS users_password, users.is_active AS users_is_active, users.is_staff AS users_is_staff, users.is_superuser AS users_is_superuser \nFROM users \nWHERE users.email = ?\n LIMIT ? OFFSET ?]\n[parameters: ('loginuser@example.com', 1, 0)]\n(Background on this error at: https://sqlalche.me/e/20/e3q8)"}
{"timestamp": "2025-10-16T00:05:23.144609", "level": "ERROR", "module": "auth", "function": "login", "line": 67, "message": "Error during login: (sqlite3.OperationalError) no such table: users\n[SQL: SELECT users.id AS users_id, users.username AS users_username, users.first_name AS users_first_name, users.last_name AS users_last_name, users.email AS users_email, users.password AS users_password, users.is_active AS users_is_active, users.is_staff AS users_is_staff, users.is_superuser AS users_is_superuser \nFROM users \nWHERE users.email = ?\n LIMIT ? OFFSET ?]\n[parameters: ('loginuser@example.com', 1, 0)]\n(Background on this error at: https://sqlalche.me/e/20/e3q8)", "exception": "Traceback (most recent call last):\n  File \"/home/ronin/devops/apibackend/.venv/lib/python3.12/site-packages/sqlalchemy/engine/base.py\", line 1967, in _exec_single_context\n    self.dialect.do_execute(\n  File \"/home/ronin/devops/apibackend/.venv/lib/python3.12/site-packages/sqlalchemy/engine/default.py\", line 951, in do_execute\n    cursor.execute(statement, parameters)\nsqlite3.OperationalError: no such table: users\n\nThe above exception was the direct cause of the following exception:\n\nTraceback (most recent call last):\n  File \"/home/ronin/devops/apibackend/routers/auth.py\", line 53, in login\n    user = db.query(User).filter(User.email == credentials.email).first()\n           ^^^^^^^^^^^^^^^^^^^^^^^^^^^^^^^^^^^^^^^^^^^^^^^^^^^^^^^^^^^^^^\n  File \"/home/ronin/devops/apibackend/.venv/lib/python3.12/site-packages/sqlalchemy/orm/query.py\", line 2759, in first\n    return self.limit(1)._iter().first()  # type: ignore\n           ^^^^^^^^^^^^^^^^^^^^^\n  File \"/home/ronin/devops/apibackend/.venv/lib/python3.12/site-packages/sqlalchemy/orm/query.py\", line 2857, in _iter\n    result: Union[ScalarResult[_T], Result[_T]] = self.session.execute(\n                                                  ^^^^^^^^^^^^^^^^^^^^^\n  File \"/home/ronin/devops/apibackend/.venv/lib/python3.12/site-packages/sqlalchemy/orm/session.py\", line 2351, in execute\n    return self._execute_internal(\n           ^^^^^^^^^^^^^^^^^^^^^^^\n  File \"/home/ronin/devops/apibackend/.venv/lib/python3.12/site-packages/sqlalchemy/orm/session.py\", line 2249, in _execute_internal\n    result: Result[Any] = compile_state_cls.orm_execute_statement(\n                          ^^^^^^^^^^^^^^^^^^^^^^^^^^^^^^^^^^^^^^^^\n  File \"/home/ronin/devops/apibackend/.venv/lib/python3.12/site-packages/sqlalchemy/orm/context.py\", line 306, in orm_execute_statement\n    result = conn.execute(\n             ^^^^^^^^^^^^^\n  File \"/home/ronin/devops/apibackend/.venv/lib/python3.12/site-packages/sqlalchemy/engine/base.py\", line 1419, in execute\n    return meth(\n           ^^^^^\n  File \"/home/ronin/devops/apibackend/.venv/lib/python3.12/site-packages/sqlalchemy/sql/elements.py\", line 526, in _execute_on_connection\n    return connection._execute_clauseelement(\n           ^^^^^^^^^^^^^^^^^^^^^^^^^^^^^^^^^^\n  File \"/home/ronin/devops/apibackend/.venv/lib/python3.12/site-packages/sqlalchemy/engine/base.py\", line 1641, in _execute_clauseelement\n    ret = self._execute_context(\n          ^^^^^^^^^^^^^^^^^^^^^^\n  File \"/home/ronin/devops/apibackend/.venv/lib/python3.12/site-packages/sqlalchemy/engine/base.py\", line 1846, in _execute_context\n    return self._exec_single_context(\n           ^^^^^^^^^^^^^^^^^^^^^^^^^^\n  File \"/home/ronin/devops/apibackend/.venv/lib/python3.12/site-packages/sqlalchemy/engine/base.py\", line 1986, in _exec_single_context\n    self._handle_dbapi_exception(\n  File \"/home/ronin/devops/apibackend/.venv/lib/python3.12/site-packages/sqlalchemy/engine/base.py\", line 2355, in _handle_dbapi_exception\n    raise sqlalchemy_exception.with_traceback(exc_info[2]) from e\n  File \"/home/ronin/devops/apibackend/.venv/lib/python3.12/site-packages/sqlalchemy/engine/base.py\", line 1967, in _exec_single_context\n    self.dialect.do_execute(\n  File \"/home/ronin/devops/apibackend/.venv/lib/python3.12/site-packages/sqlalchemy/engine/default.py\", line 951, in do_execute\n    cursor.execute(statement, parameters)\nsqlalchemy.exc.OperationalError: (sqlite3.OperationalError) no such table: users\n[SQL: SELECT users.id AS users_id, users.username AS users_username, users.first_name AS users_first_name, users.last_name AS users_last_name, users.email AS users_email, users.password AS users_password, users.is_active AS users_is_active, users.is_staff AS users_is_staff, users.is_superuser AS users_is_superuser \nFROM users \nWHERE users.email = ?\n LIMIT ? OFFSET ?]\n[parameters: ('loginuser@example.com', 1, 0)]\n(Background on this error at: https://sqlalche.me/e/20/e3q8)"}
{"timestamp": "2025-10-16T00:05:23.151786", "level": "ERROR", "module": "auth", "function": "login", "line": 67, "message": "Error during login: (sqlite3.OperationalError) no such table: users\n[SQL: SELECT users.id AS users_id, users.username AS users_username, users.first_name AS users_first_name, users.last_name AS users_last_name, users.email AS users_email, users.password AS users_password, users.is_active AS users_is_active, users.is_staff AS users_is_staff, users.is_superuser AS users_is_superuser \nFROM users \nWHERE users.email = ?\n LIMIT ? OFFSET ?]\n[parameters: ('nonexistent@example.com', 1, 0)]\n(Background on this error at: https://sqlalche.me/e/20/e3q8)", "exception": "Traceback (most recent call last):\n  File \"/home/ronin/devops/apibackend/.venv/lib/python3.12/site-packages/sqlalchemy/engine/base.py\", line 1967, in _exec_single_context\n    self.dialect.do_execute(\n  File \"/home/ronin/devops/apibackend/.venv/lib/python3.12/site-packages/sqlalchemy/engine/default.py\", line 951, in do_execute\n    cursor.execute(statement, parameters)\nsqlite3.OperationalError: no such table: users\n\nThe above exception was the direct cause of the following exception:\n\nTraceback (most recent call last):\n  File \"/home/ronin/devops/apibackend/routers/auth.py\", line 53, in login\n    user = db.query(User).filter(User.email == credentials.email).first()\n           ^^^^^^^^^^^^^^^^^^^^^^^^^^^^^^^^^^^^^^^^^^^^^^^^^^^^^^^^^^^^^^\n  File \"/home/ronin/devops/apibackend/.venv/lib/python3.12/site-packages/sqlalchemy/orm/query.py\", line 2759, in first\n    return self.limit(1)._iter().first()  # type: ignore\n           ^^^^^^^^^^^^^^^^^^^^^\n  File \"/home/ronin/devops/apibackend/.venv/lib/python3.12/site-packages/sqlalchemy/orm/query.py\", line 2857, in _iter\n    result: Union[ScalarResult[_T], Result[_T]] = self.session.execute(\n                                                  ^^^^^^^^^^^^^^^^^^^^^\n  File \"/home/ronin/devops/apibackend/.venv/lib/python3.12/site-packages/sqlalchemy/orm/session.py\", line 2351, in execute\n    return self._execute_internal(\n           ^^^^^^^^^^^^^^^^^^^^^^^\n  File \"/home/ronin/devops/apibackend/.venv/lib/python3.12/site-packages/sqlalchemy/orm/session.py\", line 2249, in _execute_internal\n    result: Result[Any] = compile_state_cls.orm_execute_statement(\n                          ^^^^^^^^^^^^^^^^^^^^^^^^^^^^^^^^^^^^^^^^\n  File \"/home/ronin/devops/apibackend/.venv/lib/python3.12/site-packages/sqlalchemy/orm/context.py\", line 306, in orm_execute_statement\n    result = conn.execute(\n             ^^^^^^^^^^^^^\n  File \"/home/ronin/devops/apibackend/.venv/lib/python3.12/site-packages/sqlalchemy/engine/base.py\", line 1419, in execute\n    return meth(\n           ^^^^^\n  File \"/home/ronin/devops/apibackend/.venv/lib/python3.12/site-packages/sqlalchemy/sql/elements.py\", line 526, in _execute_on_connection\n    return connection._execute_clauseelement(\n           ^^^^^^^^^^^^^^^^^^^^^^^^^^^^^^^^^^\n  File \"/home/ronin/devops/apibackend/.venv/lib/python3.12/site-packages/sqlalchemy/engine/base.py\", line 1641, in _execute_clauseelement\n    ret = self._execute_context(\n          ^^^^^^^^^^^^^^^^^^^^^^\n  File \"/home/ronin/devops/apibackend/.venv/lib/python3.12/site-packages/sqlalchemy/engine/base.py\", line 1846, in _execute_context\n    return self._exec_single_context(\n           ^^^^^^^^^^^^^^^^^^^^^^^^^^\n  File \"/home/ronin/devops/apibackend/.venv/lib/python3.12/site-packages/sqlalchemy/engine/base.py\", line 1986, in _exec_single_context\n    self._handle_dbapi_exception(\n  File \"/home/ronin/devops/apibackend/.venv/lib/python3.12/site-packages/sqlalchemy/engine/base.py\", line 2355, in _handle_dbapi_exception\n    raise sqlalchemy_exception.with_traceback(exc_info[2]) from e\n  File \"/home/ronin/devops/apibackend/.venv/lib/python3.12/site-packages/sqlalchemy/engine/base.py\", line 1967, in _exec_single_context\n    self.dialect.do_execute(\n  File \"/home/ronin/devops/apibackend/.venv/lib/python3.12/site-packages/sqlalchemy/engine/default.py\", line 951, in do_execute\n    cursor.execute(statement, parameters)\nsqlalchemy.exc.OperationalError: (sqlite3.OperationalError) no such table: users\n[SQL: SELECT users.id AS users_id, users.username AS users_username, users.first_name AS users_first_name, users.last_name AS users_last_name, users.email AS users_email, users.password AS users_password, users.is_active AS users_is_active, users.is_staff AS users_is_staff, users.is_superuser AS users_is_superuser \nFROM users \nWHERE users.email = ?\n LIMIT ? OFFSET ?]\n[parameters: ('nonexistent@example.com', 1, 0)]\n(Background on this error at: https://sqlalche.me/e/20/e3q8)"}
